Running BrowserMob Proxy using LittleProxy implementation. To revert to the legacy implementation, run the proxy with the command-line option '--use-littleproxy false'.
[INFO  2024-10-19T11:28:22,407 net.lightbody.bmp.proxy.Main] (main) Starting BrowserMob Proxy version 2.1.4 
[INFO  2024-10-19T11:28:22,444 org.eclipse.jetty.util.log] (main) jetty-7.x.y-SNAPSHOT 
[INFO  2024-10-19T11:28:22,473 org.eclipse.jetty.util.log] (main) started o.e.j.s.ServletContextHandler{/,null} 
[INFO  2024-10-19T11:28:22,567 org.eclipse.jetty.util.log] (main) Started SelectChannelConnector@0.0.0.0:8080 
[INFO  2024-10-19T11:28:23,288 org.littleshoot.proxy.impl.DefaultHttpProxyServer] (qtp1160850402-25) Starting proxy at address: 0.0.0.0/0.0.0.0:8081 
[INFO  2024-10-19T11:28:23,366 org.littleshoot.proxy.impl.DefaultHttpProxyServer] (qtp1160850402-25) Proxy listening with TCP transport 
[INFO  2024-10-19T11:28:23,424 org.littleshoot.proxy.impl.DefaultHttpProxyServer] (qtp1160850402-25) Proxy started at address: /0:0:0:0:0:0:0:0:8081 
2024-10-19 11:28:24,046 - INFO - Pika version 1.3.2 connecting to ('172.18.0.2', 5672)
2024-10-19 11:28:24,046 - INFO - Socket connected: <socket.socket fd=10, family=AddressFamily.AF_INET, type=SocketKind.SOCK_STREAM, proto=6, laddr=('172.18.0.3', 46470), raddr=('172.18.0.2', 5672)>
2024-10-19 11:28:24,047 - INFO - Streaming transport linked up: (<pika.adapters.utils.io_services_utils._AsyncPlaintextTransport object at 0x7fe51c60f730>, _StreamingProtocolShim: <SelectConnection PROTOCOL transport=<pika.adapters.utils.io_services_utils._AsyncPlaintextTransport object at 0x7fe51c60f730> params=<ConnectionParameters host=rabbitmq port=5672 virtual_host=/ ssl=False>>).
2024-10-19 11:28:24,049 - INFO - AMQPConnector - reporting success: <SelectConnection OPEN transport=<pika.adapters.utils.io_services_utils._AsyncPlaintextTransport object at 0x7fe51c60f730> params=<ConnectionParameters host=rabbitmq port=5672 virtual_host=/ ssl=False>>
2024-10-19 11:28:24,050 - INFO - AMQPConnectionWorkflow - reporting success: <SelectConnection OPEN transport=<pika.adapters.utils.io_services_utils._AsyncPlaintextTransport object at 0x7fe51c60f730> params=<ConnectionParameters host=rabbitmq port=5672 virtual_host=/ ssl=False>>
2024-10-19 11:28:24,050 - INFO - Connection workflow succeeded: <SelectConnection OPEN transport=<pika.adapters.utils.io_services_utils._AsyncPlaintextTransport object at 0x7fe51c60f730> params=<ConnectionParameters host=rabbitmq port=5672 virtual_host=/ ssl=False>>
2024-10-19 11:28:24,050 - INFO - Created channel=1
2024-10-19 11:28:24,051 - INFO - Successfully connected to RabbitMQ.
2024-10-19 11:28:30,824 - INFO - Found the product card layout list.
2024-10-19 11:28:30,834 - INFO - Found 10 buttons.
2024-10-19 11:28:31,892 - INFO - Clicked button 1/10.
2024-10-19 11:28:34,001 - INFO - Clicked navigate button.
2024-10-19 11:28:37,066 - INFO - Clicked button 2/10.
2024-10-19 11:28:39,138 - INFO - Clicked navigate button.
2024-10-19 11:28:42,208 - INFO - Clicked button 3/10.
2024-10-19 11:28:44,271 - INFO - Clicked navigate button.
2024-10-19 11:28:47,361 - INFO - Clicked button 4/10.
2024-10-19 11:28:49,428 - INFO - Clicked navigate button.
2024-10-19 11:28:52,495 - INFO - Clicked button 5/10.
2024-10-19 11:29:04,925 - ERROR - An error occurred while locating/clicking the navigate button: Message: 
Stacktrace:
#0 0x55c4169e80aa <unknown>
#1 0x55c4164ff1a0 <unknown>
#2 0x55c41654bd06 <unknown>
#3 0x55c41654bfa1 <unknown>
#4 0x55c416591344 <unknown>
#5 0x55c41656fdad <unknown>
#6 0x55c41658e866 <unknown>
#7 0x55c41656fb23 <unknown>
#8 0x55c41653e990 <unknown>
#9 0x55c41653f96e <unknown>
#10 0x55c4169b416b <unknown>
#11 0x55c4169b7f68 <unknown>
#12 0x55c4169a164c <unknown>
#13 0x55c4169b8ae7 <unknown>
#14 0x55c4169864af <unknown>
#15 0x55c4169d64f8 <unknown>
#16 0x55c4169d66c0 <unknown>
#17 0x55c4169e6f26 <unknown>
#18 0x7f45e3258fa3 start_thread

2024-10-19 11:29:04,927 - ERROR - Traceback (most recent call last):
  File "/app/urlCrawler.py", line 167, in capture_request_urls
    navigate_button = WebDriverWait(driver, 10).until(
  File "/usr/local/lib/python3.9/site-packages/selenium/webdriver/support/wait.py", line 105, in until
    raise TimeoutException(message, screen, stacktrace)
selenium.common.exceptions.TimeoutException: Message: 
Stacktrace:
#0 0x55c4169e80aa <unknown>
#1 0x55c4164ff1a0 <unknown>
#2 0x55c41654bd06 <unknown>
#3 0x55c41654bfa1 <unknown>
#4 0x55c416591344 <unknown>
#5 0x55c41656fdad <unknown>
#6 0x55c41658e866 <unknown>
#7 0x55c41656fb23 <unknown>
#8 0x55c41653e990 <unknown>
#9 0x55c41653f96e <unknown>
#10 0x55c4169b416b <unknown>
#11 0x55c4169b7f68 <unknown>
#12 0x55c4169a164c <unknown>
#13 0x55c4169b8ae7 <unknown>
#14 0x55c4169864af <unknown>
#15 0x55c4169d64f8 <unknown>
#16 0x55c4169d66c0 <unknown>
#17 0x55c4169e6f26 <unknown>
#18 0x7f45e3258fa3 start_thread


2024-10-19 11:29:15,268 - ERROR - An unexpected error occurred while processing button 6: Message: 
Stacktrace:
#0 0x55c4169e80aa <unknown>
#1 0x55c4164ff1a0 <unknown>
#2 0x55c41654bd06 <unknown>
#3 0x55c41654bfa1 <unknown>
#4 0x55c416591344 <unknown>
#5 0x55c41656fdad <unknown>
#6 0x55c41658e866 <unknown>
#7 0x55c41656fb23 <unknown>
#8 0x55c41653e990 <unknown>
#9 0x55c41653f96e <unknown>
#10 0x55c4169b416b <unknown>
#11 0x55c4169b7f68 <unknown>
#12 0x55c4169a164c <unknown>
#13 0x55c4169b8ae7 <unknown>
#14 0x55c4169864af <unknown>
#15 0x55c4169d64f8 <unknown>
#16 0x55c4169d66c0 <unknown>
#17 0x55c4169e6f26 <unknown>
#18 0x7f45e3258fa3 start_thread

2024-10-19 11:29:15,272 - ERROR - Traceback (most recent call last):
  File "/app/urlCrawler.py", line 132, in capture_request_urls
    product_list = WebDriverWait(driver, 10).until(
  File "/usr/local/lib/python3.9/site-packages/selenium/webdriver/support/wait.py", line 105, in until
    raise TimeoutException(message, screen, stacktrace)
selenium.common.exceptions.TimeoutException: Message: 
Stacktrace:
#0 0x55c4169e80aa <unknown>
#1 0x55c4164ff1a0 <unknown>
#2 0x55c41654bd06 <unknown>
#3 0x55c41654bfa1 <unknown>
#4 0x55c416591344 <unknown>
#5 0x55c41656fdad <unknown>
#6 0x55c41658e866 <unknown>
#7 0x55c41656fb23 <unknown>
#8 0x55c41653e990 <unknown>
#9 0x55c41653f96e <unknown>
#10 0x55c4169b416b <unknown>
#11 0x55c4169b7f68 <unknown>
#12 0x55c4169a164c <unknown>
#13 0x55c4169b8ae7 <unknown>
#14 0x55c4169864af <unknown>
#15 0x55c4169d64f8 <unknown>
#16 0x55c4169d66c0 <unknown>
#17 0x55c4169e6f26 <unknown>
#18 0x7f45e3258fa3 start_thread


2024-10-19 11:29:25,656 - ERROR - An unexpected error occurred while processing button 7: Message: 
Stacktrace:
#0 0x55c4169e80aa <unknown>
#1 0x55c4164ff1a0 <unknown>
#2 0x55c41654bd06 <unknown>
#3 0x55c41654bfa1 <unknown>
#4 0x55c416591344 <unknown>
#5 0x55c41656fdad <unknown>
#6 0x55c41658e866 <unknown>
#7 0x55c41656fb23 <unknown>
#8 0x55c41653e990 <unknown>
#9 0x55c41653f96e <unknown>
#10 0x55c4169b416b <unknown>
#11 0x55c4169b7f68 <unknown>
#12 0x55c4169a164c <unknown>
#13 0x55c4169b8ae7 <unknown>
#14 0x55c4169864af <unknown>
#15 0x55c4169d64f8 <unknown>
#16 0x55c4169d66c0 <unknown>
#17 0x55c4169e6f26 <unknown>
#18 0x7f45e3258fa3 start_thread

2024-10-19 11:29:25,660 - ERROR - Traceback (most recent call last):
  File "/app/urlCrawler.py", line 132, in capture_request_urls
    product_list = WebDriverWait(driver, 10).until(
  File "/usr/local/lib/python3.9/site-packages/selenium/webdriver/support/wait.py", line 105, in until
    raise TimeoutException(message, screen, stacktrace)
selenium.common.exceptions.TimeoutException: Message: 
Stacktrace:
#0 0x55c4169e80aa <unknown>
#1 0x55c4164ff1a0 <unknown>
#2 0x55c41654bd06 <unknown>
#3 0x55c41654bfa1 <unknown>
#4 0x55c416591344 <unknown>
#5 0x55c41656fdad <unknown>
#6 0x55c41658e866 <unknown>
#7 0x55c41656fb23 <unknown>
#8 0x55c41653e990 <unknown>
#9 0x55c41653f96e <unknown>
#10 0x55c4169b416b <unknown>
#11 0x55c4169b7f68 <unknown>
#12 0x55c4169a164c <unknown>
#13 0x55c4169b8ae7 <unknown>
#14 0x55c4169864af <unknown>
#15 0x55c4169d64f8 <unknown>
#16 0x55c4169d66c0 <unknown>
#17 0x55c4169e6f26 <unknown>
#18 0x7f45e3258fa3 start_thread


2024-10-19 11:29:36,077 - ERROR - An unexpected error occurred while processing button 8: Message: 
Stacktrace:
#0 0x55c4169e80aa <unknown>
#1 0x55c4164ff1a0 <unknown>
#2 0x55c41654bd06 <unknown>
#3 0x55c41654bfa1 <unknown>
#4 0x55c416591344 <unknown>
#5 0x55c41656fdad <unknown>
#6 0x55c41658e866 <unknown>
#7 0x55c41656fb23 <unknown>
#8 0x55c41653e990 <unknown>
#9 0x55c41653f96e <unknown>
#10 0x55c4169b416b <unknown>
#11 0x55c4169b7f68 <unknown>
#12 0x55c4169a164c <unknown>
#13 0x55c4169b8ae7 <unknown>
#14 0x55c4169864af <unknown>
#15 0x55c4169d64f8 <unknown>
#16 0x55c4169d66c0 <unknown>
#17 0x55c4169e6f26 <unknown>
#18 0x7f45e3258fa3 start_thread

2024-10-19 11:29:36,080 - ERROR - Traceback (most recent call last):
  File "/app/urlCrawler.py", line 132, in capture_request_urls
    product_list = WebDriverWait(driver, 10).until(
  File "/usr/local/lib/python3.9/site-packages/selenium/webdriver/support/wait.py", line 105, in until
    raise TimeoutException(message, screen, stacktrace)
selenium.common.exceptions.TimeoutException: Message: 
Stacktrace:
#0 0x55c4169e80aa <unknown>
#1 0x55c4164ff1a0 <unknown>
#2 0x55c41654bd06 <unknown>
#3 0x55c41654bfa1 <unknown>
#4 0x55c416591344 <unknown>
#5 0x55c41656fdad <unknown>
#6 0x55c41658e866 <unknown>
#7 0x55c41656fb23 <unknown>
#8 0x55c41653e990 <unknown>
#9 0x55c41653f96e <unknown>
#10 0x55c4169b416b <unknown>
#11 0x55c4169b7f68 <unknown>
#12 0x55c4169a164c <unknown>
#13 0x55c4169b8ae7 <unknown>
#14 0x55c4169864af <unknown>
#15 0x55c4169d64f8 <unknown>
#16 0x55c4169d66c0 <unknown>
#17 0x55c4169e6f26 <unknown>
#18 0x7f45e3258fa3 start_thread


2024-10-19 11:29:46,483 - ERROR - An unexpected error occurred while processing button 9: Message: 
Stacktrace:
#0 0x55c4169e80aa <unknown>
#1 0x55c4164ff1a0 <unknown>
#2 0x55c41654bd06 <unknown>
#3 0x55c41654bfa1 <unknown>
#4 0x55c416591344 <unknown>
#5 0x55c41656fdad <unknown>
#6 0x55c41658e866 <unknown>
#7 0x55c41656fb23 <unknown>
#8 0x55c41653e990 <unknown>
#9 0x55c41653f96e <unknown>
#10 0x55c4169b416b <unknown>
#11 0x55c4169b7f68 <unknown>
#12 0x55c4169a164c <unknown>
#13 0x55c4169b8ae7 <unknown>
#14 0x55c4169864af <unknown>
#15 0x55c4169d64f8 <unknown>
#16 0x55c4169d66c0 <unknown>
#17 0x55c4169e6f26 <unknown>
#18 0x7f45e3258fa3 start_thread

2024-10-19 11:29:46,486 - ERROR - Traceback (most recent call last):
  File "/app/urlCrawler.py", line 132, in capture_request_urls
    product_list = WebDriverWait(driver, 10).until(
  File "/usr/local/lib/python3.9/site-packages/selenium/webdriver/support/wait.py", line 105, in until
    raise TimeoutException(message, screen, stacktrace)
selenium.common.exceptions.TimeoutException: Message: 
Stacktrace:
#0 0x55c4169e80aa <unknown>
#1 0x55c4164ff1a0 <unknown>
#2 0x55c41654bd06 <unknown>
#3 0x55c41654bfa1 <unknown>
#4 0x55c416591344 <unknown>
#5 0x55c41656fdad <unknown>
#6 0x55c41658e866 <unknown>
#7 0x55c41656fb23 <unknown>
#8 0x55c41653e990 <unknown>
#9 0x55c41653f96e <unknown>
#10 0x55c4169b416b <unknown>
#11 0x55c4169b7f68 <unknown>
#12 0x55c4169a164c <unknown>
#13 0x55c4169b8ae7 <unknown>
#14 0x55c4169864af <unknown>
#15 0x55c4169d64f8 <unknown>
#16 0x55c4169d66c0 <unknown>
#17 0x55c4169e6f26 <unknown>
#18 0x7f45e3258fa3 start_thread


2024-10-19 11:29:56,895 - ERROR - An unexpected error occurred while processing button 10: Message: 
Stacktrace:
#0 0x55c4169e80aa <unknown>
#1 0x55c4164ff1a0 <unknown>
#2 0x55c41654bd06 <unknown>
#3 0x55c41654bfa1 <unknown>
#4 0x55c416591344 <unknown>
#5 0x55c41656fdad <unknown>
#6 0x55c41658e866 <unknown>
#7 0x55c41656fb23 <unknown>
#8 0x55c41653e990 <unknown>
#9 0x55c41653f96e <unknown>
#10 0x55c4169b416b <unknown>
#11 0x55c4169b7f68 <unknown>
#12 0x55c4169a164c <unknown>
#13 0x55c4169b8ae7 <unknown>
#14 0x55c4169864af <unknown>
#15 0x55c4169d64f8 <unknown>
#16 0x55c4169d66c0 <unknown>
#17 0x55c4169e6f26 <unknown>
#18 0x7f45e3258fa3 start_thread

2024-10-19 11:29:56,898 - ERROR - Traceback (most recent call last):
  File "/app/urlCrawler.py", line 132, in capture_request_urls
    product_list = WebDriverWait(driver, 10).until(
  File "/usr/local/lib/python3.9/site-packages/selenium/webdriver/support/wait.py", line 105, in until
    raise TimeoutException(message, screen, stacktrace)
selenium.common.exceptions.TimeoutException: Message: 
Stacktrace:
#0 0x55c4169e80aa <unknown>
#1 0x55c4164ff1a0 <unknown>
#2 0x55c41654bd06 <unknown>
#3 0x55c41654bfa1 <unknown>
#4 0x55c416591344 <unknown>
#5 0x55c41656fdad <unknown>
#6 0x55c41658e866 <unknown>
#7 0x55c41656fb23 <unknown>
#8 0x55c41653e990 <unknown>
#9 0x55c41653f96e <unknown>
#10 0x55c4169b416b <unknown>
#11 0x55c4169b7f68 <unknown>
#12 0x55c4169a164c <unknown>
#13 0x55c4169b8ae7 <unknown>
#14 0x55c4169864af <unknown>
#15 0x55c4169d64f8 <unknown>
#16 0x55c4169d66c0 <unknown>
#17 0x55c4169e6f26 <unknown>
#18 0x7f45e3258fa3 start_thread


2024-10-19 11:29:57,001 - INFO - 

#################################################


2024-10-19 11:29:57,002 - INFO - Published URL to queue: https://www.mcdonalds.com/dnaapp/itemList?country=NO&language=no&showLiveData=true&nutrient_req=Y&item=200503%28%29-200506%28%29-200437%28%29-200011%28%29-200019%28%29-200145%28%29-200020%28%29-200015%28%29-200014%28%29-200017%28%29-200179%28%29-200180%28%29-200131%28%29-200132%28%29-
2024-10-19 11:29:57,002 - INFO - Published URL to queue: https://www.mcdonalds.com/dnaapp/itemList?country=NO&language=no&showLiveData=true&nutrient_req=Y&item=200504%28%29-200507%28%29-200338%28%29-200496%28%29-200497%28%29-200438%28%29-200231%28%29-200032%28%29-200026%28%29-200247%28%29-200028%28%29-200280%28%29-
2024-10-19 11:29:57,003 - INFO - Published URL to queue: https://www.mcdonalds.com/dnaapp/itemList?country=NO&language=no&showLiveData=true&nutrient_req=Y&item=200505%28%29-200508%28%29-200439%28%29-200355%28%29-200354%28%29-200353%28%29-200284%28%29-
2024-10-19 11:29:57,004 - INFO - Published URL to queue: https://www.mcdonalds.com/dnaapp/itemList?country=NO&language=no&showLiveData=true&nutrient_req=Y&item=200461%28%29-200031%28%29-200268%28%29-200035%28%29-200024%28%29-200111%28%29-200475%28%29-
2024-10-19 11:29:57,004 - INFO - Published URL to queue: https://www.mcdonalds.com/dnaapp/itemList?country=NO&language=no&showLiveData=true&nutrient_req=Y&item=200093%28%29-200095%28%29-200100%28%29-200101%28%29-200096%28%29-200198%28%29-200102%28%29-200097%28%29-
2024-10-19 11:29:57,005 - INFO - Closing connection (200): Normal shutdown
2024-10-19 11:29:57,005 - INFO - Closing channel (200): 'Normal shutdown' on <Channel number=1 OPEN conn=<SelectConnection OPEN transport=<pika.adapters.utils.io_services_utils._AsyncPlaintextTransport object at 0x7fe51c60f730> params=<ConnectionParameters host=rabbitmq port=5672 virtual_host=/ ssl=False>>>
2024-10-19 11:29:57,006 - INFO - Received <Channel.CloseOk> on <Channel number=1 CLOSING conn=<SelectConnection OPEN transport=<pika.adapters.utils.io_services_utils._AsyncPlaintextTransport object at 0x7fe51c60f730> params=<ConnectionParameters host=rabbitmq port=5672 virtual_host=/ ssl=False>>>
2024-10-19 11:29:57,006 - INFO - Closing connection (200): 'Normal shutdown'
2024-10-19 11:29:57,007 - INFO - Aborting transport connection: state=1; <socket.socket fd=10, family=AddressFamily.AF_INET, type=SocketKind.SOCK_STREAM, proto=6, laddr=('172.18.0.3', 46470), raddr=('172.18.0.2', 5672)>
2024-10-19 11:29:57,007 - INFO - _AsyncTransportBase._initate_abort(): Initiating abrupt asynchronous transport shutdown: state=1; error=None; <socket.socket fd=10, family=AddressFamily.AF_INET, type=SocketKind.SOCK_STREAM, proto=6, laddr=('172.18.0.3', 46470), raddr=('172.18.0.2', 5672)>
2024-10-19 11:29:57,008 - INFO - Deactivating transport: state=1; <socket.socket fd=10, family=AddressFamily.AF_INET, type=SocketKind.SOCK_STREAM, proto=6, laddr=('172.18.0.3', 46470), raddr=('172.18.0.2', 5672)>
2024-10-19 11:29:57,008 - INFO - AMQP stack terminated, failed to connect, or aborted: opened=True, error-arg=None; pending-error=ConnectionClosedByClient: (200) 'Normal shutdown'
2024-10-19 11:29:57,008 - INFO - Stack terminated due to ConnectionClosedByClient: (200) 'Normal shutdown'
2024-10-19 11:29:57,008 - INFO - Closing transport socket and unlinking: state=3; <socket.socket fd=10, family=AddressFamily.AF_INET, type=SocketKind.SOCK_STREAM, proto=6, laddr=('172.18.0.3', 46470), raddr=('172.18.0.2', 5672)>
2024-10-19 11:29:57,009 - INFO - User-initiated close: result=BlockingConnection__OnClosedArgs(connection=<SelectConnection CLOSED transport=None params=<ConnectionParameters host=rabbitmq port=5672 virtual_host=/ ssl=False>>, error=ConnectionClosedByClient: (200) 'Normal shutdown')
2024-10-19 11:29:57,009 - INFO - RabbitMQ connection closed.
2024-10-19 11:29:57,083 - INFO - Browsermob-Proxy server stopped and Selenium WebDriver closed.
